Traceback (most recent call last):
  File "D:\classification_test\.venv\Lib\site-packages\wandb\sdk\wandb_config.py", line 162, in __getattr__
    return self.__getitem__(key)
           ^^^^^^^^^^^^^^^^^^^^^
  File "D:\classification_test\.venv\Lib\site-packages\wandb\sdk\wandb_config.py", line 130, in __getitem__
    return self._items[key]
           ~~~~~~~~~~~^^^^^
KeyError: 'batch_size'
The above exception was the direct cause of the following exception:
Traceback (most recent call last):
  File "D:\classification_test\train.py", line 142, in <module>
    n_steps_per_epoch = math.ceil(len(train_dl.dataset) / config.batch_size)
                                                          ^^^^^^^^^^^^^^^^^
  File "D:\classification_test\.venv\Lib\site-packages\wandb\sdk\wandb_config.py", line 164, in __getattr__
    raise AttributeError(
AttributeError: <class 'wandb.sdk.wandb_config.Config'> object has no attribute 'batch_size'